Workbook
Name n_200: 'Data Analysis Addin'!$J$1
Name n_200: SPY_close_price!#REF!
Name n_200: SPY_close_price_PQ!#REF!
Name n_200: #REF!
Name n_50: 'Data Analysis Addin'!$I$1
Name n_50: SPY_close_price!#REF!
Name n_50: SPY_close_price_PQ!#REF!
Name n_50: #REF!
Name NativeTimeline_Date: #N/A

Sheet SPY_close_price_PQ
A2: Date | B2: Close
A3: 44137 | B3: 330.2
A4: 44138 | B4: 336.03
A5: 44139 | B5: 343.54
A6: 44140 | B6: 350.24
A7: 44141 | B7: 350.16
A8: 44144 | B8: 354.56
A9: 44145 | B9: 354.04
A10: 44146 | B10: 356.67
A11: 44147 | B11: 353.21
A12: 44148 | B12: 358.1
A13: 44151 | B13: 362.57
A14: 44152 | B14: 360.62
... A1258: 45961 | B1258: 682.06

Sheet SPY_close_price
C1: 50 | D1: 200
A2: Date | B2: Close | C2: 50-MA | D2: 200-MA | E2: Golden Cross
A3: 44137 | B3: 330.2 | C3: =AVERAGE(OFFSET(SPY_Close_Price_PQ[[#This Row],[Close]], 0, 0, $C$1*-1)) -> #REF! | D3: =AVERAGE(OFFSET(SPY_Close_Price_PQ[[#This Row],[Close]], 0, 0, $D$1*-1)) -> #REF! | E3: =IF(AND(C2<D2,C3>D3),1,0) -> #REF!
A4: 44138 | B4: 336.03 | C4: =AVERAGE(OFFSET(SPY_Close_Price_PQ[[#This Row],[Close]], 0, 0, $C$1*-1)) -> #REF! | D4: =AVERAGE(OFFSET(SPY_Close_Price_PQ[[#This Row],[Close]], 0, 0, $D$1*-1)) -> #REF! | E4: =IF(AND(C3<D3,C4>D4),1,0) -> #REF!
A5: 44139 | B5: 343.54 | C5: =AVERAGE(OFFSET(SPY_Close_Price_PQ[[#This Row],[Close]], 0, 0, $C$1*-1)) -> #REF! | D5: =AVERAGE(OFFSET(SPY_Close_Price_PQ[[#This Row],[Close]], 0, 0, $D$1*-1)) -> #REF! | E5: =IF(AND(C4<D4,C5>D5),1,0) -> #REF!
A6: 44140 | B6: 350.24 | C6: =AVERAGE(OFFSET(SPY_Close_Price_PQ[[#This Row],[Close]], 0, 0, $C$1*-1)) -> #REF! | D6: =AVERAGE(OFFSET(SPY_Close_Price_PQ[[#This Row],[Close]], 0, 0, $D$1*-1)) -> #REF! | E6: =IF(AND(C5<D5,C6>D6),1,0) -> #REF!
A7: 44141 | B7: 350.16 | C7: =AVERAGE(OFFSET(SPY_Close_Price_PQ[[#This Row],[Close]], 0, 0, $C$1*-1)) -> #REF! | D7: =AVERAGE(OFFSET(SPY_Close_Price_PQ[[#This Row],[Close]], 0, 0, $D$1*-1)) -> #REF! | E7: =IF(AND(C6<D6,C7>D7),1,0) -> #REF!
A8: 44144 | B8: 354.56 | C8: =AVERAGE(OFFSET(SPY_Close_Price_PQ[[#This Row],[Close]], 0, 0, $C$1*-1)) -> #REF! | D8: =AVERAGE(OFFSET(SPY_Close_Price_PQ[[#This Row],[Close]], 0, 0, $D$1*-1)) -> #REF! | E8: =IF(AND(C7<D7,C8>D8),1,0) -> #REF!
A9: 44145 | B9: 354.04 | C9: =AVERAGE(OFFSET(SPY_Close_Price_PQ[[#This Row],[Close]], 0, 0, $C$1*-1)) -> #REF! | D9: =AVERAGE(OFFSET(SPY_Close_Price_PQ[[#This Row],[Close]], 0, 0, $D$1*-1)) -> #REF! | E9: =IF(AND(C8<D8,C9>D9),1,0) -> #REF!
A10: 44146 | B10: 356.67 | C10: =AVERAGE(OFFSET(SPY_Close_Price_PQ[[#This Row],[Close]], 0, 0, $C$1*-1)) -> #REF! | D10: =AVERAGE(OFFSET(SPY_Close_Price_PQ[[#This Row],[Close]], 0, 0, $D$1*-1)) -> #REF! | E10: =IF(AND(C9<D9,C10>D10),1,0) -> #REF!
A11: 44147 | B11: 353.21 | C11: =AVERAGE(OFFSET(SPY_Close_Price_PQ[[#This Row],[Close]], 0, 0, $C$1*-1)) -> #REF! | D11: =AVERAGE(OFFSET(SPY_Close_Price_PQ[[#This Row],[Close]], 0, 0, $D$1*-1)) -> #REF! | E11: =IF(AND(C10<D10,C11>D11),1,0) -> #REF!
A12: 44148 | B12: 358.1 | C12: =AVERAGE(OFFSET(SPY_Close_Price_PQ[[#This Row],[Close]], 0, 0, $C$1*-1)) -> #REF! | D12: =AVERAGE(OFFSET(SPY_Close_Price_PQ[[#This Row],[Close]], 0, 0, $D$1*-1)) -> #REF! | E12: =IF(AND(C11<D11,C12>D12),1,0) -> #REF!
A13: 44151 | B13: 362.57 | C13: =AVERAGE(OFFSET(SPY_Close_Price_PQ[[#This Row],[Close]], 0, 0, $C$1*-1)) -> #REF! | D13: =AVERAGE(OFFSET(SPY_Close_Price_PQ[[#This Row],[Close]], 0, 0, $D$1*-1)) -> #REF! | E13: =IF(AND(C12<D12,C13>D13),1,0) -> #REF!
A14: 44152 | B14: 360.62 | C14: =AVERAGE(OFFSET(SPY_Close_Price_PQ[[#This Row],[Close]], 0, 0, $C$1*-1)) -> #REF! | D14: =AVERAGE(OFFSET(SPY_Close_Price_PQ[[#This Row],[Close]], 0, 0, $D$1*-1)) -> #REF! | E14: =IF(AND(C13<D13,C14>D14),1,0) -> #REF!
... A1258: 45961 | B1258: 682.06 | C1258: =AVERAGE(OFFSET(SPY_Close_Price_PQ[[#This Row],[Close]], 0, 0, $C$1*-1)) -> 662.172 | D1258: =AVERAGE(OFFSET(SPY_Close_Price_PQ[[#This Row],[Close]], 0, 0, $D$1*-1)) -> 609.442 | E1258: =IF(AND(C1257<D1257,C1258>D1258),1,0) -> 0

Sheet Data Analysis Addin
I1: 50 | J1: 200
A2: Date | B2: Close | C2: 50-Day MA | D2: 200-Day MA | G2: 50-Day Average | H2: 200-Day Average | I2: Golden Cross | J2: Death Cross | K2: Year
A3: 44137 | B3: 330.2 | C3: #N/A | D3: #N/A | G3: =AVERAGE(OFFSET($B3,0,0,-(MIN(ROW()-ROW($B$3)+1,n_50)),1)) -> 330.2 | H3: =AVERAGE(OFFSET($B3,0,0,-(MIN(ROW()-ROW($B$3)+1,n_200)),1)) -> 330.2 | I3: =IF(AND('Data Analysis Addin'!$G3<='Data Analysis Addin'!$H3,G4>H4), 1, 0) -> 0 | J3: =IF($G3<$H3,1,0) -> 0 | K3: =YEAR('Data Analysis Addin'!$A3) -> 2020 | N3: Data Drills by Maven Analytics | Turning Bullish | Q3: {=_xlfn.UNIQUE('Data Analysis Addin'!$K$3:$K$1258)} -> 2020
A4: 44138 | B4: 336.03 | C4: #N/A | D4: #N/A | G4: =AVERAGE(OFFSET($B4,0,0,-(MIN(ROW()-ROW($B$3)+1,n_50)),1)) -> 333.115 | H4: =AVERAGE(OFFSET($B4,0,0,-(MIN(ROW()-ROW($B$3)+1,n_200)),1)) -> 333.115 | I4: =IF(AND('Data Analysis Addin'!$G4<='Data Analysis Addin'!$H4,G5>H5), 1, 0) -> 0 | J4: =IF($G4<$H4,1,0) -> 0 | K4: =YEAR('Data Analysis Addin'!$A4) -> 2020 | N4: Dynamic Moving Averages with *new* MAP Function | Q4: 2021
A5: 44139 | B5: 343.54 | C5: #N/A | D5: #N/A | G5: =AVERAGE(OFFSET($B5,0,0,-(MIN(ROW()-ROW($B$3)+1,n_50)),1)) -> 336.59 | H5: =AVERAGE(OFFSET($B5,0,0,-(MIN(ROW()-ROW($B$3)+1,n_200)),1)) -> 336.59 | I5: =IF(AND('Data Analysis Addin'!$G5<='Data Analysis Addin'!$H5,G6>H6), 1, 0) -> 0 | J5: =IF($G5<$H5,1,0) -> 0 | K5: =YEAR('Data Analysis Addin'!$A5) -> 2020 | Q5: 2022
A6: 44140 | B6: 350.24 | C6: #N/A | D6: #N/A | G6: =AVERAGE(OFFSET($B6,0,0,-(MIN(ROW()-ROW($B$3)+1,n_50)),1)) -> 340.0025 | H6: =AVERAGE(OFFSET($B6,0,0,-(MIN(ROW()-ROW($B$3)+1,n_200)),1)) -> 340.0025 | I6: =IF(AND('Data Analysis Addin'!$G6<='Data Analysis Addin'!$H6,G7>H7), 1, 0) -> 0 | J6: =IF($G6<$H6,1,0) -> 0 | K6: =YEAR('Data Analysis Addin'!$A6) -> 2020 | Q6: 2023
A7: 44141 | B7: 350.16 | C7: #N/A | D7: #N/A | G7: =AVERAGE(OFFSET($B7,0,0,-(MIN(ROW()-ROW($B$3)+1,n_50)),1)) -> 342.034 | H7: =AVERAGE(OFFSET($B7,0,0,-(MIN(ROW()-ROW($B$3)+1,n_200)),1)) -> 342.034 | I7: =IF(AND('Data Analysis Addin'!$G7<='Data Analysis Addin'!$H7,G8>H8), 1, 0) -> 0 | J7: =IF($G7<$H7,1,0) -> 0 | K7: =YEAR('Data Analysis Addin'!$A7) -> 2020 | Q7: 2024
A8: 44144 | B8: 354.56 | C8: #N/A | D8: #N/A | G8: =AVERAGE(OFFSET($B8,0,0,-(MIN(ROW()-ROW($B$3)+1,n_50)),1)) -> 344.12167 | H8: =AVERAGE(OFFSET($B8,0,0,-(MIN(ROW()-ROW($B$3)+1,n_200)),1)) -> 344.12167 | I8: =IF(AND('Data Analysis Addin'!$G8<='Data Analysis Addin'!$H8,G9>H9), 1, 0) -> 0 | J8: =IF($G8<$H8,1,0) -> 0 | K8: =YEAR('Data Analysis Addin'!$A8) -> 2020 | Q8: 2025
A9: 44145 | B9: 354.04 | C9: #N/A | D9: #N/A | G9: =AVERAGE(OFFSET($B9,0,0,-(MIN(ROW()-ROW($B$3)+1,n_50)),1)) -> 345.53857 | H9: =AVERAGE(OFFSET($B9,0,0,-(MIN(ROW()-ROW($B$3)+1,n_200)),1)) -> 345.53857 | I9: =IF(AND('Data Analysis Addin'!$G9<='Data Analysis Addin'!$H9,G10>H10), 1, 0) -> 0 | J9: =IF($G9<$H9,1,0) -> 0 | K9: =YEAR('Data Analysis Addin'!$A9) -> 2020
A10: 44146 | B10: 356.67 | C10: #N/A | D10: #N/A | G10: =AVERAGE(OFFSET($B10,0,0,-(MIN(ROW()-ROW($B$3)+1,n_50)),1)) -> 346.93 | H10: =AVERAGE(OFFSET($B10,0,0,-(MIN(ROW()-ROW($B$3)+1,n_200)),1)) -> 346.93 | I10: =IF(AND('Data Analysis Addin'!$G10<='Data Analysis Addin'!$H10,G11>H11), 1, 0) -> 0 | J10: =IF($G10<$H10,1,0) -> 0 | K10: =YEAR('Data Analysis Addin'!$A10) -> 2020
A11: 44147 | B11: 353.21 | C11: #N/A | D11: #N/A | G11: =AVERAGE(OFFSET($B11,0,0,-(MIN(ROW()-ROW($B$3)+1,n_50)),1)) -> 347.62778 | H11: =AVERAGE(OFFSET($B11,0,0,-(MIN(ROW()-ROW($B$3)+1,n_200)),1)) -> 347.62778 | I11: =IF(AND('Data Analysis Addin'!$G11<='Data Analysis Addin'!$H11,G12>H12), 1, 0) -> 0 | J11: =IF($G11<$H11,1,0) -> 0 | K11: =YEAR('Data Analysis Addin'!$A11) -> 2020
A12: 44148 | B12: 358.1 | C12: #N/A | D12: #N/A | G12: =AVERAGE(OFFSET($B12,0,0,-(MIN(ROW()-ROW($B$3)+1,n_50)),1)) -> 348.675 | H12: =AVERAGE(OFFSET($B12,0,0,-(MIN(ROW()-ROW($B$3)+1,n_200)),1)) -> 348.675 | I12: =IF(AND('Data Analysis Addin'!$G12<='Data Analysis Addin'!$H12,G13>H13), 1, 0) -> 0 | J12: =IF($G12<$H12,1,0) -> 0 | K12: =YEAR('Data Analysis Addin'!$A12) -> 2020
A13: 44151 | B13: 362.57 | C13: #N/A | D13: #N/A | G13: =AVERAGE(OFFSET($B13,0,0,-(MIN(ROW()-ROW($B$3)+1,n_50)),1)) -> 349.93818 | H13: =AVERAGE(OFFSET($B13,0,0,-(MIN(ROW()-ROW($B$3)+1,n_200)),1)) -> 349.93818 | I13: =IF(AND('Data Analysis Addin'!$G13<='Data Analysis Addin'!$H13,G14>H14), 1, 0) -> 0 | J13: =IF($G13<$H13,1,0) -> 0 | K13: =YEAR('Data Analysis Addin'!$A13) -> 2020
A14: 44152 | B14: 360.62 | C14: #N/A | D14: #N/A | G14: =AVERAGE(OFFSET($B14,0,0,-(MIN(ROW()-ROW($B$3)+1,n_50)),1)) -> 350.82833 | H14: =AVERAGE(OFFSET($B14,0,0,-(MIN(ROW()-ROW($B$3)+1,n_200)),1)) -> 350.82833 | I14: =IF(AND('Data Analysis Addin'!$G14<='Data Analysis Addin'!$H14,G15>H15), 1, 0) -> 0 | J14: =IF($G14<$H14,1,0) -> 0 | K14: =YEAR('Data Analysis Addin'!$A14) -> 2020
A15: 44153 | B15: 356.28 | C15: #N/A | D15: #N/A | G15: =AVERAGE(OFFSET($B15,0,0,-(MIN(ROW()-ROW($B$3)+1,n_50)),1)) -> 351.24769 | H15: =AVERAGE(OFFSET($B15,0,0,-(MIN(ROW()-ROW($B$3)+1,n_200)),1)) -> 351.24769 | I15: =IF(AND('Data Analysis Addin'!$G15<='Data Analysis Addin'!$H15,G16>H16), 1, 0) -> 0 | J15: =IF($G15<$H15,1,0) -> 0 | K15: =YEAR('Data Analysis Addin'!$A15) -> 2020
A16: 44154 | B16: 357.78 | C16: #N/A | D16: #N/A | G16: =AVERAGE(OFFSET($B16,0,0,-(MIN(ROW()-ROW($B$3)+1,n_50)),1)) -> 351.71429 | H16: =AVERAGE(OFFSET($B16,0,0,-(MIN(ROW()-ROW($B$3)+1,n_200)),1)) -> 351.71429 | I16: =IF(AND('Data Analysis Addin'!$G16<='Data Analysis Addin'!$H16,G17>H17), 1, 0) -> 0 | J16: =IF($G16<$H16,1,0) -> 0 | K16: =YEAR('Data Analysis Addin'!$A16) -> 2020
A17: 44155 | B17: 355.33 | C17: #N/A | D17: #N/A | G17: =AVERAGE(OFFSET($B17,0,0,-(MIN(ROW()-ROW($B$3)+1,n_50)),1)) -> 351.95533 | H17: =AVERAGE(OFFSET($B17,0,0,-(MIN(ROW()-ROW($B$3)+1,n_200)),1)) -> 351.95533 | I17: =IF(AND('Data Analysis Addin'!$G17<='Data Analysis Addin'!$H17,G18>H18), 1, 0) -> 0 | J17: =IF($G17<$H17,1,0) -> 0 | K17: =YEAR('Data Analysis Addin'!$A17) -> 2020
A18: 44158 | B18: 357.46 | C18: #N/A | D18: #N/A | G18: =AVERAGE(OFFSET($B18,0,0,-(MIN(ROW()-ROW($B$3)+1,n_50)),1)) -> 352.29937 | H18: =AVERAGE(OFFSET($B18,0,0,-(MIN(ROW()-ROW($B$3)+1,n_200)),1)) -> 352.29937 | I18: =IF(AND('Data Analysis Addin'!$G18<='Data Analysis Addin'!$H18,G19>H19), 1, 0) -> 0 | J18: =IF($G18<$H18,1,0) -> 0 | K18: =YEAR('Data Analysis Addin'!$A18) -> 2020
A19: 44159 | B19: 363.22 | C19: #N/A | D19: #N/A | G19: =AVERAGE(OFFSET($B19,0,0,-(MIN(ROW()-ROW($B$3)+1,n_50)),1)) -> 352.94176 | H19: =AVERAGE(OFFSET($B19,0,0,-(MIN(ROW()-ROW($B$3)+1,n_200)),1)) -> 352.94176 | I19: =IF(AND('Data Analysis Addin'!$G19<='Data Analysis Addin'!$H19,G20>H20), 1, 0) -> 0 | J19: =IF($G19<$H19,1,0) -> 0 | K19: =YEAR('Data Analysis Addin'!$A19) -> 2020
A20: 44160 | B20: 362.66 | C20: #N/A | D20: #N/A | G20: =AVERAGE(OFFSET($B20,0,0,-(MIN(ROW()-ROW($B$3)+1,n_50)),1)) -> 353.48167 | H20: =AVERAGE(OFFSET($B20,0,0,-(MIN(ROW()-ROW($B$3)+1,n_200)),1)) -> 353.48167 | I20: =IF(AND('Data Analysis Addin'!$G20<='Data Analysis Addin'!$H20,G21>H21), 1, 0) -> 0 | J20: =IF($G20<$H20,1,0) -> 0 | K20: =YEAR('Data Analysis Addin'!$A20) -> 2020
... A51: 44208 | B51: 378.77 | C51: #N/A | D51: #N/A | G51: =AVERAGE(OFFSET($B51,0,0,-(MIN(ROW()-ROW($B$3)+1,n_50)),1)) -> 363.98755 | H51: =AVERAGE(OFFSET($B51,0,0,-(MIN(ROW()-ROW($B$3)+1,n_200)),1)) -> 363.98755 | I51: =IF(AND('Data Analysis Addin'!$G51<='Data Analysis Addin'!$H51,G52>H52), 1, 0) -> 0 | J51: =IF($G51<$H51,1,0) -> 0 | K51: =YEAR('Data Analysis Addin'!$A51) -> 2021
A52: 44209 | B52: 379.79 | C52: =AVERAGE(B3:B52) -> 364.3036 | D52: #N/A | G52: =AVERAGE(OFFSET($B52,0,0,-(MIN(ROW()-ROW($B$3)+1,n_50)),1)) -> 364.3036 | H52: =AVERAGE(OFFSET($B52,0,0,-(MIN(ROW()-ROW($B$3)+1,n_200)),1)) -> 364.3036 | I52: =IF(AND('Data Analysis Addin'!$G52<='Data Analysis Addin'!$H52,G53>H53), 1, 0) -> 1 | J52: =IF($G52<$H52,1,0) -> 0 | K52: =YEAR('Data Analysis Addin'!$A52) -> 2021
A53: 44210 | B53: 378.46 | C53: =AVERAGE(B4:B53) -> 365.2688 | D53: #N/A | G53: =AVERAGE(OFFSET($B53,0,0,-(MIN(ROW()-ROW($B$3)+1,n_50)),1)) -> 365.2688 | H53: =AVERAGE(OFFSET($B53,0,0,-(MIN(ROW()-ROW($B$3)+1,n_200)),1)) -> 364.58118 | I53: =IF(AND('Data Analysis Addin'!$G53<='Data Analysis Addin'!$H53,G54>H54), 1, 0) -> 0 | J53: =IF($G53<$H53,1,0) -> 0 | K53: =YEAR('Data Analysis Addin'!$A53) -> 2021
A54: 44211 | B54: 375.7 | C54: =AVERAGE(B5:B54) -> 366.0622 | D54: #N/A | G54: =AVERAGE(OFFSET($B54,0,0,-(MIN(ROW()-ROW($B$3)+1,n_50)),1)) -> 366.0622 | H54: =AVERAGE(OFFSET($B54,0,0,-(MIN(ROW()-ROW($B$3)+1,n_200)),1)) -> 364.795 | I54: =IF(AND('Data Analysis Addin'!$G54<='Data Analysis Addin'!$H54,G55>H55), 1, 0) -> 0 | J54: =IF($G54<$H54,1,0) -> 0 | K54: =YEAR('Data Analysis Addin'!$A54) -> 2021
A55: 44215 | B55: 378.65 | C55: =AVERAGE(B6:B55) -> 366.7644 | D55: #N/A | G55: =AVERAGE(OFFSET($B55,0,0,-(MIN(ROW()-ROW($B$3)+1,n_50)),1)) -> 366.7644 | H55: =AVERAGE(OFFSET($B55,0,0,-(MIN(ROW()-ROW($B$3)+1,n_200)),1)) -> 365.05642 | I55: =IF(AND('Data Analysis Addin'!$G55<='Data Analysis Addin'!$H55,G56>H56), 1, 0) -> 0 | J55: =IF($G55<$H55,1,0) -> 0 | K55: =YEAR('Data Analysis Addin'!$A55) -> 2021
A56: 44216 | B56: 383.89 | C56: =AVERAGE(B7:B56) -> 367.4374 | D56: #N/A | G56: =AVERAGE(OFFSET($B56,0,0,-(MIN(ROW()-ROW($B$3)+1,n_50)),1)) -> 367.4374 | H56: =AVERAGE(OFFSET($B56,0,0,-(MIN(ROW()-ROW($B$3)+1,n_200)),1)) -> 365.40519 | I56: =IF(AND('Data Analysis Addin'!$G56<='Data Analysis Addin'!$H56,G57>H57), 1, 0) -> 0 | J56: =IF($G56<$H56,1,0) -> 0 | K56: =YEAR('Data Analysis Addin'!$A56) -> 2021
A57: 44217 | B57: 384.24 | C57: =AVERAGE(B8:B57) -> 368.119 | D57: #N/A | G57: =AVERAGE(OFFSET($B57,0,0,-(MIN(ROW()-ROW($B$3)+1,n_50)),1)) -> 368.119 | H57: =AVERAGE(OFFSET($B57,0,0,-(MIN(ROW()-ROW($B$3)+1,n_200)),1)) -> 365.74764 | I57: =IF(AND('Data Analysis Addin'!$G57<='Data Analysis Addin'!$H57,G58>H58), 1, 0) -> 0 | J57: =IF($G57<$H57,1,0) -> 0 | K57: =YEAR('Data Analysis Addin'!$A57) -> 2021
A58: 44218 | B58: 382.88 | C58: =AVERAGE(B9:B58) -> 368.6854 | D58: #N/A | G58: =AVERAGE(OFFSET($B58,0,0,-(MIN(ROW()-ROW($B$3)+1,n_50)),1)) -> 368.6854 | H58: =AVERAGE(OFFSET($B58,0,0,-(MIN(ROW()-ROW($B$3)+1,n_200)),1)) -> 366.05357 | I58: =IF(AND('Data Analysis Addin'!$G58<='Data Analysis Addin'!$H58,G59>H59), 1, 0) -> 0 | J58: =IF($G58<$H58,1,0) -> 0 | K58: =YEAR('Data Analysis Addin'!$A58) -> 2021
A59: 44221 | B59: 384.39 | C59: =AVERAGE(B10:B59) -> 369.2924 | D59: #N/A | G59: =AVERAGE(OFFSET($B59,0,0,-(MIN(ROW()-ROW($B$3)+1,n_50)),1)) -> 369.2924 | H59: =AVERAGE(OFFSET($B59,0,0,-(MIN(ROW()-ROW($B$3)+1,n_200)),1)) -> 366.37526 | I59: =IF(AND('Data Analysis Addin'!$G59<='Data Analysis Addin'!$H59,G60>H60), 1, 0) -> 0 | J59: =IF($G59<$H59,1,0) -> 0 | K59: =YEAR('Data Analysis Addin'!$A59) -> 2021
A60: 44222 | B60: 383.79 | C60: =AVERAGE(B11:B60) -> 369.8348 | D60: #N/A | G60: =AVERAGE(OFFSET($B60,0,0,-(MIN(ROW()-ROW($B$3)+1,n_50)),1)) -> 369.8348 | H60: =AVERAGE(OFFSET($B60,0,0,-(MIN(ROW()-ROW($B$3)+1,n_200)),1)) -> 366.67552 | I60: =IF(AND('Data Analysis Addin'!$G60<='Data Analysis Addin'!$H60,G61>H61), 1, 0) -> 0 | J60: =IF($G60<$H60,1,0) -> 0 | K60: =YEAR('Data Analysis Addin'!$A60) -> 2021
A61: 44223 | B61: 374.41 | C61: =AVERAGE(B12:B61) -> 370.2588 | D61: #N/A | G61: =AVERAGE(OFFSET($B61,0,0,-(MIN(ROW()-ROW($B$3)+1,n_50)),1)) -> 370.2588 | H61: =AVERAGE(OFFSET($B61,0,0,-(MIN(ROW()-ROW($B$3)+1,n_200)),1)) -> 366.80661 | I61: =IF(AND('Data Analysis Addin'!$G61<='Data Analysis Addin'!$H61,G62>H62), 1, 0) -> 0 | J61: =IF($G61<$H61,1,0) -> 0 | K61: =YEAR('Data Analysis Addin'!$A61) -> 2021
A62: 44224 | B62: 377.63 | C62: =AVERAGE(B13:B62) -> 370.6494 | D62: #N/A | G62: =AVERAGE(OFFSET($B62,0,0,-(MIN(ROW()-ROW($B$3)+1,n_50)),1)) -> 370.6494 | H62: =AVERAGE(OFFSET($B62,0,0,-(MIN(ROW()-ROW($B$3)+1,n_200)),1)) -> 366.987 | I62: =IF(AND('Data Analysis Addin'!$G62<='Data Analysis Addin'!$H62,G63>H63), 1, 0) -> 0 | J62: =IF($G62<$H62,1,0) -> 0 | K62: =YEAR('Data Analysis Addin'!$A62) -> 2021
A63: 44225 | B63: 370.07 | C63: =AVERAGE(B14:B63) -> 370.7994 | D63: #N/A | G63: =AVERAGE(OFFSET($B63,0,0,-(MIN(ROW()-ROW($B$3)+1,n_50)),1)) -> 370.7994 | H63: =AVERAGE(OFFSET($B63,0,0,-(MIN(ROW()-ROW($B$3)+1,n_200)),1)) -> 367.03754 | I63: =IF(AND('Data Analysis Addin'!$G63<='Data Analysis Addin'!$H63,G64>H64), 1, 0) -> 0 | J63: =IF($G63<$H63,1,0) -> 0 | K63: =YEAR('Data Analysis Addin'!$A63) -> 2021
... A201: 44425 | B201: 444.04 | C201: =AVERAGE(B152:B201) -> 433.0336 | D201: #N/A | G201: =AVERAGE(OFFSET($B201,0,0,-(MIN(ROW()-ROW($B$3)+1,n_50)),1)) -> 433.0336 | H201: =AVERAGE(OFFSET($B201,0,0,-(MIN(ROW()-ROW($B$3)+1,n_200)),1)) -> 399.36648 | I201: =IF(AND('Data Analysis Addin'!$G201<='Data Analysis Addin'!$H201,G202>H202), 1, 0) -> 0 | J201: =IF($G201<$H201,1,0) -> 0 | K201: =YEAR('Data Analysis Addin'!$A201) -> 2021
A202: 44426 | B202: 439.18 | C202: =AVERAGE(B153:B202) -> 433.3716 | D202: =AVERAGE(B3:B202) -> 399.56555 | G202: =AVERAGE(OFFSET($B202,0,0,-(MIN(ROW()-ROW($B$3)+1,n_50)),1)) -> 433.3716 | H202: =AVERAGE(OFFSET($B202,0,0,-(MIN(ROW()-ROW($B$3)+1,n_200)),1)) -> 399.56555 | I202: =IF(AND('Data Analysis Addin'!$G202<='Data Analysis Addin'!$H202,G203>H203), 1, 0) -> 0 | J202: =IF($G202<$H202,1,0) -> 0 | K202: =YEAR('Data Analysis Addin'!$A202) -> 2021
A203: 44427 | B203: 439.86 | C203: =AVERAGE(B154:B203) -> 433.7358 | D203: =AVERAGE(B4:B203) -> 400.11385 | G203: =AVERAGE(OFFSET($B203,0,0,-(MIN(ROW()-ROW($B$3)+1,n_50)),1)) -> 433.7358 | H203: =AVERAGE(OFFSET($B203,0,0,-(MIN(ROW()-ROW($B$3)+1,n_200)),1)) -> 400.11385 | I203: =IF(AND('Data Analysis Addin'!$G203<='Data Analysis Addin'!$H203,G204>H204), 1, 0) -> 0 | J203: =IF($G203<$H203,1,0) -> 0 | K203: =YEAR('Data Analysis Addin'!$A203) -> 2021
A204: 44428 | B204: 443.36 | C204: =AVERAGE(B155:B204) -> 434.1308 | D204: =AVERAGE(B5:B204) -> 400.6505 | G204: =AVERAGE(OFFSET($B204,0,0,-(MIN(ROW()-ROW($B$3)+1,n_50)),1)) -> 434.1308 | H204: =AVERAGE(OFFSET($B204,0,0,-(MIN(ROW()-ROW($B$3)+1,n_200)),1)) -> 400.6505 | I204: =IF(AND('Data Analysis Addin'!$G204<='Data Analysis Addin'!$H204,G205>H205), 1, 0) -> 0 | J204: =IF($G204<$H204,1,0) -> 0 | K204: =YEAR('Data Analysis Addin'!$A204) -> 2021
A205: 44431 | B205: 447.26 | C205: =AVERAGE(B156:B205) -> 434.5898 | D205: =AVERAGE(B6:B205) -> 401.1691 | G205: =AVERAGE(OFFSET($B205,0,0,-(MIN(ROW()-ROW($B$3)+1,n_50)),1)) -> 434.5898 | H205: =AVERAGE(OFFSET($B205,0,0,-(MIN(ROW()-ROW($B$3)+1,n_200)),1)) -> 401.1691 | I205: =IF(AND('Data Analysis Addin'!$G205<='Data Analysis Addin'!$H205,G206>H206), 1, 0) -> 0 | J205: =IF($G205<$H205,1,0) -> 0 | K205: =YEAR('Data Analysis Addin'!$A205) -> 2021
A206: 44432 | B206: 447.97 | C206: =AVERAGE(B157:B206) -> 435.044 | D206: =AVERAGE(B7:B206) -> 401.65775 | G206: =AVERAGE(OFFSET($B206,0,0,-(MIN(ROW()-ROW($B$3)+1,n_50)),1)) -> 435.044 | H206: =AVERAGE(OFFSET($B206,0,0,-(MIN(ROW()-ROW($B$3)+1,n_200)),1)) -> 401.65775 | I206: =IF(AND('Data Analysis Addin'!$G206<='Data Analysis Addin'!$H206,G207>H207), 1, 0) -> 0 | J206: =IF($G206<$H206,1,0) -> 0 | K206: =YEAR('Data Analysis Addin'!$A206) -> 2021
A207: 44433 | B207: 448.91 | C207: =AVERAGE(B158:B207) -> 435.5326 | D207: =AVERAGE(B8:B207) -> 402.1515 | G207: =AVERAGE(OFFSET($B207,0,0,-(MIN(ROW()-ROW($B$3)+1,n_50)),1)) -> 435.5326 | H207: =AVERAGE(OFFSET($B207,0,0,-(MIN(ROW()-ROW($B$3)+1,n_200)),1)) -> 402.1515 | I207: =IF(AND('Data Analysis Addin'!$G207<='Data Analysis Addin'!$H207,G208>H208), 1, 0) -> 0 | J207: =IF($G207<$H207,1,0) -> 0 | K207: =YEAR('Data Analysis Addin'!$A207) -> 2021
...

Sheet Close_Moving_Averages
A1: Date | B1: Close | C1: 50-Day-MovingAverage | D1: 200-Day-MovingAverage | E1: Golden Cross
A2: 44137 | B2: 330.2 | E2: =IF(AND(C2>D2, C1<D1), 1, 0) -> 0
A3: 44138 | B3: 336.03 | E3: =IF(AND(C3>D3, C2<D2), 1, 0) -> 0 | G3: Row Labels | H3: CP | I3: 50Day-MA | J3: 200Day-MA | K3: Golden_Cross | N3: Golden Cross Dates
A4: 44139 | B4: 343.54 | E4: =IF(AND(C4>D4, C3<D3), 1, 0) -> 0 | G4: 44137 | H4: 330.2 | K4: 0
A5: 44140 | B5: 350.24 | E5: =IF(AND(C5>D5, C4<D4), 1, 0) -> 0 | G5: 44138 | H5: 336.03 | K5: 0 | N5: {=_xlfn._xlws.FILTER(Close_Moving_Averages[Date], Close_Moving_Averages[Golden Cross]=1)} -> 44959
A6: 44141 | B6: 350.16 | E6: =IF(AND(C6>D6, C5<D5), 1, 0) -> 0 | G6: 44139 | H6: 343.54 | K6: 0 | N6: 45839
A7: 44144 | B7: 354.56 | E7: =IF(AND(C7>D7, C6<D6), 1, 0) -> 0 | G7: 44140 | H7: 350.24 | K7: 0
A8: 44145 | B8: 354.04 | E8: =IF(AND(C8>D8, C7<D7), 1, 0) -> 0 | G8: 44141 | H8: 350.16 | K8: 0
A9: 44146 | B9: 356.67 | E9: =IF(AND(C9>D9, C8<D8), 1, 0) -> 0 | G9: 44144 | H9: 354.56 | K9: 0
A10: 44147 | B10: 353.21 | E10: =IF(AND(C10>D10, C9<D9), 1, 0) -> 0 | G10: 44145 | H10: 354.04 | K10: 0
A11: 44148 | B11: 358.1 | E11: =IF(AND(C11>D11, C10<D10), 1, 0) -> 0 | G11: 44146 | H11: 356.67 | K11: 0
A12: 44151 | B12: 362.57 | E12: =IF(AND(C12>D12, C11<D11), 1, 0) -> 0 | G12: 44147 | H12: 353.21 | K12: 0
A13: 44152 | B13: 360.62 | E13: =IF(AND(C13>D13, C12<D12), 1, 0) -> 0 | G13: 44148 | H13: 358.1 | K13: 0
A14: 44153 | B14: 356.28 | E14: =IF(AND(C14>D14, C13<D13), 1, 0) -> 0 | G14: 44151 | H14: 362.57 | K14: 0
A15: 44154 | B15: 357.78 | E15: =IF(AND(C15>D15, C14<D14), 1, 0) -> 0 | G15: 44152 | H15: 360.62 | K15: 0
A16: 44155 | B16: 355.33 | E16: =IF(AND(C16>D16, C15<D15), 1, 0) -> 0 | G16: 44153 | H16: 356.28 | K16: 0
A17: 44158 | B17: 357.46 | E17: =IF(AND(C17>D17, C16<D16), 1, 0) -> 0 | G17: 44154 | H17: 357.78 | K17: 0
A18: 44159 | B18: 363.22 | E18: =IF(AND(C18>D18, C17<D17), 1, 0) -> 0 | G18: 44155 | H18: 355.33 | K18: 0
... A50: 44208 | B50: 378.77 | E50: =IF(AND(C50>D50, C49<D49), 1, 0) -> 0 | G50: 44204 | H50: 381.26 | K50: 0
A51: 44209 | B51: 379.79 | C51: 364.3036 | E51: =IF(AND(C51>D51, C50<D50), 1, 0) -> 0 | G51: 44207 | H51: 378.69 | K51: 0
A52: 44210 | B52: 378.46 | C52: 365.2688 | E52: =IF(AND(C52>D52, C51<D51), 1, 0) -> 0 | G52: 44208 | H52: 378.77 | K52: 0
A53: 44211 | B53: 375.7 | C53: 366.0622 | E53: =IF(AND(C53>D53, C52<D52), 1, 0) -> 0 | G53: 44209 | H53: 379.79 | I53: 364.3036 | K53: 0
A54: 44215 | B54: 378.65 | C54: 366.7644 | E54: =IF(AND(C54>D54, C53<D53), 1, 0) -> 0 | G54: 44210 | H54: 378.46 | I54: 365.2688 | K54: 0
A55: 44216 | B55: 383.89 | C55: 367.4374 | E55: =IF(AND(C55>D55, C54<D54), 1, 0) -> 0 | G55: 44211 | H55: 375.7 | I55: 366.0622 | K55: 0
A56: 44217 | B56: 384.24 | C56: 368.119 | E56: =IF(AND(C56>D56, C55<D55), 1, 0) -> 0 | G56: 44215 | H56: 378.65 | I56: 366.7644 | K56: 0
A57: 44218 | B57: 382.88 | C57: 368.6854 | E57: =IF(AND(C57>D57, C56<D56), 1, 0) -> 0 | G57: 44216 | H57: 383.89 | I57: 367.4374 | K57: 0
A58: 44221 | B58: 384.39 | C58: 369.2924 | E58: =IF(AND(C58>D58, C57<D57), 1, 0) -> 0 | G58: 44217 | H58: 384.24 | I58: 368.119 | K58: 0
A59: 44222 | B59: 383.79 | C59: 369.8348 | E59: =IF(AND(C59>D59, C58<D58), 1, 0) -> 0 | G59: 44218 | H59: 382.88 | I59: 368.6854 | K59: 0
A60: 44223 | B60: 374.41 | C60: 370.2588 | E60: =IF(AND(C60>D60, C59<D59), 1, 0) -> 0 | G60: 44221 | H60: 384.39 | I60: 369.2924 | K60: 0
A61: 44224 | B61: 377.63 | C61: 370.6494 | E61: =IF(AND(C61>D61, C60<D60), 1, 0) -> 0 | G61: 44222 | H61: 383.79 | I61: 369.8348 | K61: 0
A62: 44225 | B62: 370.07 | C62: 370.7994 | E62: =IF(AND(C62>D62, C61<D61), 1, 0) -> 0 | G62: 44223 | H62: 374.41 | I62: 370.2588 | K62: 0
A63: 44228 | B63: 376.23 | C63: 371.1116 | E63: =IF(AND(C63>D63, C62<D62), 1, 0) -> 0 | G63: 44224 | H63: 377.63 | I63: 370.6494 | K63: 0
A64: 44229 | B64: 381.55 | C64: 371.617 | E64: =IF(AND(C64>D64, C63<D63), 1, 0) -> 0 | G64: 44225 | H64: 370.07 | I64: 370.7994 | K64: 0
... A200: 44425 | B200: 444.04 | C200: 433.0336 | E200: =IF(AND(C200>D200, C199<D199), 1, 0) -> 0 | G200: 44421 | H200: 445.92 | I200: 432.1092 | K200: 0
A201: 44426 | B201: 439.18 | C201: 433.3716 | D201: 399.5656 | E201: =IF(AND(C201>D201, C200<D200), 1, 0) -> 0 | G201: 44424 | H201: 446.97 | I201: 432.5966 | K201: 0
A202: 44427 | B202: 439.86 | C202: 433.7358 | D202: 400.1138 | E202: =IF(AND(C202>D202, C201<D201), 1, 0) -> 0 | G202: 44425 | H202: 444.04 | I202: 433.0336 | K202: 0
A203: 44428 | B203: 443.36 | C203: 434.1308 | D203: 400.6505 | E203: =IF(AND(C203>D203, C202<D202), 1, 0) -> 0 | G203: 44426 | H203: 439.18 | I203: 433.3716 | J203: 399.5656 | K203: 0
A204: 44431 | B204: 447.26 | C204: 434.5898 | D204: 401.1691 | E204: =IF(AND(C204>D204, C203<D203), 1, 0) -> 0 | G204: 44427 | H204: 439.86 | I204: 433.7358 | J204: 400.1138 | K204: 0
A205: 44432 | B205: 447.97 | C205: 435.044 | D205: 401.6578 | E205: =IF(AND(C205>D205, C204<D204), 1, 0) -> 0 | G205: 44428 | H205: 443.36 | I205: 434.1308 | J205: 400.6505 | K205: 0
A206: 44433 | B206: 448.91 | C206: 435.5326 | D206: 402.1515 | E206: =IF(AND(C206>D206, C205<D205), 1, 0) -> 0 | G206: 44431 | H206: 447.26 | I206: 434.5898 | J206: 401.1691 | K206: 0
...

Sheet Golden Cross

Sheet M Language code
A1: 50-Day-Moving-Average M Code
A3: let
A4: Source = Excel.CurrentWorkbook(){[Name="SPY_Close_Price"]}[Content],
A5: #"Changed Type" = Table.TransformColumnTypes(Source,{{"Date", type date}, {"Close", type number}}),
A6: #"Added Index" = Table.AddIndexColumn(#"Changed Type", "Index", 1, 1, Int64.Type),
A7: #"Reordered Columns" = Table.ReorderColumns(#"Added Index",{"Index", "Date", "Close"}),
A8: #"Added Custom" = Table.AddColumn(#"Reordered Columns", "ValueList", each #"Reordered Columns"[Close]),
A9: #"Added Custom1" = Table.AddColumn(#"Added Custom", "Range50", each if ([Index] < 50) then "" else List.Range([ValueList], _[Index] - 50, 50)),
A10: #"Added Custom2" = Table.AddColumn(#"Added Custom1", "50-Day-MovingAverage", each if [Range50] = "" then "" else List.Average([Range50])),
A11: #"Removed Columns" = Table.RemoveColumns(#"Added Custom2",{"Index", "ValueList", "Range50"}),
A12: #"Changed Type1" = Table.TransformColumnTypes(#"Removed Columns",{{"50-Day-MovingAverage", Currency.Type}, {"Close", Currency.Type}})
A13: in
... A31: #"Changed Type1"
